Workbook

Sheet Pre-Tx
C1: PERIODONTAL CHART | AE1: BOP | AI1: =BB13 | AN1: Plaque | AS1: =BB12 | BA1: perio-chart-template:3
C2: Patient | U2: HN | AE2: Date | AO2: Examiner
C3: Stage of therapy | J3: FALSE | K3: Pre-treatment | Q3: FALSE | R3: Re-evaluation | X3: FALSE | Y3: Recall (SPT) | AE3: Age | AO3: Teeth present | AV3: =32-COUNTIF(C54:AX54,"X")-COUNTIF(C56:AX56,"X")
C4: LOCAL ETIOLOGIC AND CONTRIBUTING FACTORS
C5: FALSE | D5: Inadequate oral hygiene | O5: FALSE | P5: Supragingival calculus | AA5: FALSE | AB5: Subgingival calculus | AM5: FALSE | AN5: Food impaction
C6: FALSE | D6: Related caries | O6: FALSE | P6: Improper embrasure | AA6: FALSE | AB6: Malposed tooth | AM6: FALSE | AN6: Anatomical predisposing factor
C7: FALSE | D7: Traumatic occlusion | O7: FALSE | P7: Defective prostheses | AA7: FALSE | AB7: Defective fillings | AM7: FALSE | AN7: High muscle attachment
A9: MAXILLA | C9: 18 | F9: 17 | I9: 16 | L9: 15 | O9: 14 | R9: 13 | U9: 12 | X9: 11 | AA9: 21 | AD9: 22 | AG9: 23 | AJ9: 24 | AM9: 25 | AP9: 26 | AS9: 27 | AV9: 28 | BA9: SUMMARY
A10: BUCCAL | B10: KG | AY10: KG | BA10: Teeth present | BB10: =AV3
B11: PLAQUE | AY11: PLAQUE | BA11: Total sites | BB11: =BB10*6
B12: BOP | AY12: BOP | BA12: Plaque score | BB12: =IF(BB11=0,"",(COUNTIF(C11:AX11,"/")+COUNTIF(C27:AX27,"/")+COUNTIF(C32:AX32,"/")+COUNTIF(C48:AX48,"/"))/BB11)
B13: CEJ-GM | AY13: CEJ-GM | BA13: BOP | BB13: =IF(BB11=0,"",(COUNTIF(C12:AX12,"+")+COUNTIF(C26:AX26,"+")+COUNTIF(C33:AX33,"+")+COUNTIF(C47:AX47,"+"))/BB11)
B14: PD | AY14: PD
B15: CAL | C15: =IF(C14="","",C14+N(C13)) | D15: =IF(D14="","",D14+N(D13)) | E15: =IF(E14="","",E14+N(E13)) | F15: =IF(F14="","",F14+N(F13)) | G15: =IF(G14="","",G14+N(G13)) | H15: =IF(H14="","",H14+N(H13)) | I15: =IF(I14="","",I14+N(I13)) | J15: =IF(J14="","",J14+N(J13)) | ... AX15: =IF(AX14="","",AX14+N(AX13)) | AY15: CAL | BA15: PD (sites) | BB15: Sites | BC15: %
BA16: 1-3 mm | BB16: =COUNTIFS(C14:AX14,">=1",C14:AX14,"<=3")+COUNTIFS(C24:AX24,">=1",C24:AX24,"<=3")+COUNTIFS(C35:AX35,">=1",C35:AX35,"<=3")+COUNTIFS(C45:AX45,">=1",C45:AX45,"<=3") | BC16: =IF($BB$11=0,"",BB16/$BB$11)
BA17: 4-6 mm | BB17: =COUNTIFS(C14:AX14,">=4",C14:AX14,"<=6")+COUNTIFS(C24:AX24,">=4",C24:AX24,"<=6")+COUNTIFS(C35:AX35,">=4",C35:AX35,"<=6")+COUNTIFS(C45:AX45,">=4",C45:AX45,"<=6") | BC17: =IF($BB$11=0,"",BB17/$BB$11)
BA18: 7 mm or more | BB18: =COUNTIF(C14:AX14,">=7")+COUNTIF(C24:AX24,">=7")+COUNTIF(C35:AX35,">=7")+COUNTIF(C45:AX45,">=7") | BC18: =IF($BB$11=0,"",BB18/$BB$11)
BA20: CAL (sites) | BB20: Sites | BC20: %
BA21: 1-2 mm | BB21: =COUNTIFS(C15:AX15,">=1",C15:AX15,"<=2")+COUNTIFS(C23:AX23,">=1",C23:AX23,"<=2")+COUNTIFS(C36:AX36,">=1",C36:AX36,"<=2")+COUNTIFS(C44:AX44,">=1",C44:AX44,"<=2") | BC21: =IF($BB$11=0,"",BB21/$BB$11)
BA22: 3-4 mm | BB22: =COUNTIFS(C15:AX15,">=3",C15:AX15,"<=4")+COUNTIFS(C23:AX23,">=3",C23:AX23,"<=4")+COUNTIFS(C36:AX36,">=3",C36:AX36,"<=4")+COUNTIFS(C44:AX44,">=3",C44:AX44,"<=4") | BC22: =IF($BB$11=0,"",BB22/$BB$11)
A23: PALATAL | B23: CAL | C23: =IF(C24="","",C24+N(C25)) | D23: =IF(D24="","",D24+N(D25)) | E23: =IF(E24="","",E24+N(E25)) | F23: =IF(F24="","",F24+N(F25)) | G23: =IF(G24="","",G24+N(G25)) | H23: =IF(H24="","",H24+N(H25)) | I23: =IF(I24="","",I24+N(I25)) | J23: =IF(J24="","",J24+N(J25)) | ... AX23: =IF(AX24="","",AX24+N(AX25)) | AY23: CAL | BA23: 5 mm or more | BB23: =COUNTIF(C15:AX15,">=5")+COUNTIF(C23:AX23,">=5")+COUNTIF(C36:AX36,">=5")+COUNTIF(C44:AX44,">=5") | BC23: =IF($BB$11=0,"",BB23/$BB$11)
B24: PD | AY24: PD
B25: CEJ-GM | AY25: CEJ-GM
B26: BOP | AY26: BOP
B27: PLAQUE | AY27: PLAQUE
A28: MAXILLA | C28: 18 | F28: 17 | I28: 16 | L28: 15 | O28: 14 | R28: 13 | U28: 12 | X28: 11 | AA28: 21 | AD28: 22 | AG28: 23 | AJ28: 24 | AM28: 25 | AP28: 26 | AS28: 27 | AV28: 28
A31: MANDIBLE | C31: 48 | F31: 47 | I31: 46 | L31: 45 | O31: 44 | R31: 43 | U31: 42 | X31: 41 | AA31: 31 | AD31: 32 | AG31: 33 | AJ31: 34 | AM31: 35 | AP31: 36 | AS31: 37 | AV31: 38
A32: LINGUAL | B32: PLAQUE | AY32: PLAQUE
B33: BOP | AY33: BOP
B34: CEJ-GM | AY34: CEJ-GM
B35: PD | AY35: PD
B36: CAL | C36: =IF(C35="","",C35+N(C34)) | D36: =IF(D35="","",D35+N(D34)) | E36: =IF(E35="","",E35+N(E34)) | F36: =IF(F35="","",F35+N(F34)) | G36: =IF(G35="","",G35+N(G34)) | H36: =IF(H35="","",H35+N(H34)) | I36: =IF(I35="","",I35+N(I34)) | J36: =IF(J35="","",J35+N(J34)) | ... AX36: =IF(AX35="","",AX35+N(AX34)) | AY36: CAL
A44: BUCCAL | B44: CAL | C44: =IF(C45="","",C45+N(C46)) | D44: =IF(D45="","",D45+N(D46)) | E44: =IF(E45="","",E45+N(E46)) | F44: =IF(F45="","",F45+N(F46)) | G44: =IF(G45="","",G45+N(G46)) | H44: =IF(H45="","",H45+N(H46)) | I44: =IF(I45="","",I45+N(I46)) | J44: =IF(J45="","",J45+N(J46)) | ... AX44: =IF(AX45="","",AX45+N(AX46)) | AY44: CAL
B45: PD | AY45: PD
B46: CEJ-GM | AY46: CEJ-GM
B47: BOP | AY47: BOP
B48: PLAQUE | AY48: PLAQUE
B49: KG | AY49: KG
A50: MANDIBLE | C50: 48 | F50: 47 | I50: 46 | L50: 45 | O50: 44 | R50: 43 | U50: 42 | X50: 41 | AA50: 31 | AD50: 32 | AG50: 33 | AJ50: 34 | AM50: 35 | AP50: 36 | AS50: 37 | AV50: 38
C52: MISSING TEETH AND IMPLANTS (not printed) · X = missing, crosses the tooth out · I = implant (to draw it, right-click the drawing > Change Picture)
...

Sheet Eva
C1: PERIODONTAL CHART | AE1: BOP | AI1: =BB13 | AN1: Plaque | AS1: =BB12 | BA1: perio-chart-template:3
C2: Patient | U2: HN | AE2: Date | AO2: Examiner
C3: Stage of therapy | J3: FALSE | K3: Pre-treatment | Q3: FALSE | R3: Re-evaluation | X3: FALSE | Y3: Recall (SPT) | AE3: Age | AO3: Teeth present | AV3: =32-COUNTIF(C54:AX54,"X")-COUNTIF(C56:AX56,"X")
C4: LOCAL ETIOLOGIC AND CONTRIBUTING FACTORS
C5: FALSE | D5: Inadequate oral hygiene | O5: FALSE | P5: Supragingival calculus | AA5: FALSE | AB5: Subgingival calculus | AM5: FALSE | AN5: Food impaction
C6: FALSE | D6: Related caries | O6: FALSE | P6: Improper embrasure | AA6: FALSE | AB6: Malposed tooth | AM6: FALSE | AN6: Anatomical predisposing factor
C7: FALSE | D7: Traumatic occlusion | O7: FALSE | P7: Defective prostheses | AA7: FALSE | AB7: Defective fillings | AM7: FALSE | AN7: High muscle attachment
A9: MAXILLA | C9: 18 | F9: 17 | I9: 16 | L9: 15 | O9: 14 | R9: 13 | U9: 12 | X9: 11 | AA9: 21 | AD9: 22 | AG9: 23 | AJ9: 24 | AM9: 25 | AP9: 26 | AS9: 27 | AV9: 28 | BA9: SUMMARY
A10: BUCCAL | B10: KG | AY10: KG | BA10: Teeth present | BB10: =AV3
B11: PLAQUE | AY11: PLAQUE | BA11: Total sites | BB11: =BB10*6
B12: BOP | AY12: BOP | BA12: Plaque score | BB12: =IF(BB11=0,"",(COUNTIF(C11:AX11,"/")+COUNTIF(C27:AX27,"/")+COUNTIF(C32:AX32,"/")+COUNTIF(C48:AX48,"/"))/BB11)
B13: CEJ-GM | AY13: CEJ-GM | BA13: BOP | BB13: =IF(BB11=0,"",(COUNTIF(C12:AX12,"+")+COUNTIF(C26:AX26,"+")+COUNTIF(C33:AX33,"+")+COUNTIF(C47:AX47,"+"))/BB11)
B14: PD | AY14: PD
B15: CAL | C15: =IF(C14="","",C14+N(C13)) | D15: =IF(D14="","",D14+N(D13)) | E15: =IF(E14="","",E14+N(E13)) | F15: =IF(F14="","",F14+N(F13)) | G15: =IF(G14="","",G14+N(G13)) | H15: =IF(H14="","",H14+N(H13)) | I15: =IF(I14="","",I14+N(I13)) | J15: =IF(J14="","",J14+N(J13)) | ... AX15: =IF(AX14="","",AX14+N(AX13)) | AY15: CAL | BA15: PD (sites) | BB15: Sites | BC15: %
BA16: 1-3 mm | BB16: =COUNTIFS(C14:AX14,">=1",C14:AX14,"<=3")+COUNTIFS(C24:AX24,">=1",C24:AX24,"<=3")+COUNTIFS(C35:AX35,">=1",C35:AX35,"<=3")+COUNTIFS(C45:AX45,">=1",C45:AX45,"<=3") | BC16: =IF($BB$11=0,"",BB16/$BB$11)
BA17: 4-6 mm | BB17: =COUNTIFS(C14:AX14,">=4",C14:AX14,"<=6")+COUNTIFS(C24:AX24,">=4",C24:AX24,"<=6")+COUNTIFS(C35:AX35,">=4",C35:AX35,"<=6")+COUNTIFS(C45:AX45,">=4",C45:AX45,"<=6") | BC17: =IF($BB$11=0,"",BB17/$BB$11)
BA18: 7 mm or more | BB18: =COUNTIF(C14:AX14,">=7")+COUNTIF(C24:AX24,">=7")+COUNTIF(C35:AX35,">=7")+COUNTIF(C45:AX45,">=7") | BC18: =IF($BB$11=0,"",BB18/$BB$11)
BA20: CAL (sites) | BB20: Sites | BC20: %
BA21: 1-2 mm | BB21: =COUNTIFS(C15:AX15,">=1",C15:AX15,"<=2")+COUNTIFS(C23:AX23,">=1",C23:AX23,"<=2")+COUNTIFS(C36:AX36,">=1",C36:AX36,"<=2")+COUNTIFS(C44:AX44,">=1",C44:AX44,"<=2") | BC21: =IF($BB$11=0,"",BB21/$BB$11)
BA22: 3-4 mm | BB22: =COUNTIFS(C15:AX15,">=3",C15:AX15,"<=4")+COUNTIFS(C23:AX23,">=3",C23:AX23,"<=4")+COUNTIFS(C36:AX36,">=3",C36:AX36,"<=4")+COUNTIFS(C44:AX44,">=3",C44:AX44,"<=4") | BC22: =IF($BB$11=0,"",BB22/$BB$11)
A23: PALATAL | B23: CAL | C23: =IF(C24="","",C24+N(C25)) | D23: =IF(D24="","",D24+N(D25)) | E23: =IF(E24="","",E24+N(E25)) | F23: =IF(F24="","",F24+N(F25)) | G23: =IF(G24="","",G24+N(G25)) | H23: =IF(H24="","",H24+N(H25)) | I23: =IF(I24="","",I24+N(I25)) | J23: =IF(J24="","",J24+N(J25)) | ... AX23: =IF(AX24="","",AX24+N(AX25)) | AY23: CAL | BA23: 5 mm or more | BB23: =COUNTIF(C15:AX15,">=5")+COUNTIF(C23:AX23,">=5")+COUNTIF(C36:AX36,">=5")+COUNTIF(C44:AX44,">=5") | BC23: =IF($BB$11=0,"",BB23/$BB$11)
B24: PD | AY24: PD
B25: CEJ-GM | AY25: CEJ-GM
B26: BOP | AY26: BOP
B27: PLAQUE | AY27: PLAQUE
A28: MAXILLA | C28: 18 | F28: 17 | I28: 16 | L28: 15 | O28: 14 | R28: 13 | U28: 12 | X28: 11 | AA28: 21 | AD28: 22 | AG28: 23 | AJ28: 24 | AM28: 25 | AP28: 26 | AS28: 27 | AV28: 28
A31: MANDIBLE | C31: 48 | F31: 47 | I31: 46 | L31: 45 | O31: 44 | R31: 43 | U31: 42 | X31: 41 | AA31: 31 | AD31: 32 | AG31: 33 | AJ31: 34 | AM31: 35 | AP31: 36 | AS31: 37 | AV31: 38
A32: LINGUAL | B32: PLAQUE | AY32: PLAQUE
B33: BOP | AY33: BOP
B34: CEJ-GM | AY34: CEJ-GM
B35: PD | AY35: PD
B36: CAL | C36: =IF(C35="","",C35+N(C34)) | D36: =IF(D35="","",D35+N(D34)) | E36: =IF(E35="","",E35+N(E34)) | F36: =IF(F35="","",F35+N(F34)) | G36: =IF(G35="","",G35+N(G34)) | H36: =IF(H35="","",H35+N(H34)) | I36: =IF(I35="","",I35+N(I34)) | J36: =IF(J35="","",J35+N(J34)) | ... AX36: =IF(AX35="","",AX35+N(AX34)) | AY36: CAL
A44: BUCCAL | B44: CAL | C44: =IF(C45="","",C45+N(C46)) | D44: =IF(D45="","",D45+N(D46)) | E44: =IF(E45="","",E45+N(E46)) | F44: =IF(F45="","",F45+N(F46)) | G44: =IF(G45="","",G45+N(G46)) | H44: =IF(H45="","",H45+N(H46)) | I44: =IF(I45="","",I45+N(I46)) | J44: =IF(J45="","",J45+N(J46)) | ... AX44: =IF(AX45="","",AX45+N(AX46)) | AY44: CAL
B45: PD | AY45: PD
B46: CEJ-GM | AY46: CEJ-GM
B47: BOP | AY47: BOP
B48: PLAQUE | AY48: PLAQUE
B49: KG | AY49: KG
A50: MANDIBLE | C50: 48 | F50: 47 | I50: 46 | L50: 45 | O50: 44 | R50: 43 | U50: 42 | X50: 41 | AA50: 31 | AD50: 32 | AG50: 33 | AJ50: 34 | AM50: 35 | AP50: 36 | AS50: 37 | AV50: 38
C52: MISSING TEETH AND IMPLANTS (not printed) · X = missing, crosses the tooth out · I = implant (to draw it, right-click the drawing > Change Picture)
...

Sheet Compare
C1: PERIODONTAL CHART — CHANGE | AA1: Re-evaluation minus pre-treatment
C2: Patient | F2: ='Pre-Tx'!F2&"" | U2: HN | W2: ='Pre-Tx'!W2&"" | AE2: Date | AH2: ='Pre-Tx'!AH2&"" | AO2: Examiner | AS2: ='Pre-Tx'!AS2&""
C3: Green: improvement (PD or CAL reduced). Red: worse. Plaque and BOP rows show the re-evaluation marks.
A9: MAXILLA | C9: 18 | F9: 17 | I9: 16 | L9: 15 | O9: 14 | R9: 13 | U9: 12 | X9: 11 | AA9: 21 | AD9: 22 | AG9: 23 | AJ9: 24 | AM9: 25 | AP9: 26 | AS9: 27 | AV9: 28
A10: BUCCAL | B10: KG | C10: =IF(OR(Eva!C10="",'Pre-Tx'!C10=""),"",Eva!C10-'Pre-Tx'!C10) | D10: =IF(OR(Eva!D10="",'Pre-Tx'!D10=""),"",Eva!D10-'Pre-Tx'!D10) | E10: =IF(OR(Eva!E10="",'Pre-Tx'!E10=""),"",Eva!E10-'Pre-Tx'!E10) | F10: =IF(OR(Eva!F10="",'Pre-Tx'!F10=""),"",Eva!F10-'Pre-Tx'!F10) | G10: =IF(OR(Eva!G10="",'Pre-Tx'!G10=""),"",Eva!G10-'Pre-Tx'!G10) | H10: =IF(OR(Eva!H10="",'Pre-Tx'!H10=""),"",Eva!H10-'Pre-Tx'!H10) | I10: =IF(OR(Eva!I10="",'Pre-Tx'!I10=""),"",Eva!I10-'Pre-Tx'!I10) | J10: =IF(OR(Eva!J10="",'Pre-Tx'!J10=""),"",Eva!J10-'Pre-Tx'!J10) | ... AX10: =IF(OR(Eva!AX10="",'Pre-Tx'!AX10=""),"",Eva!AX10-'Pre-Tx'!AX10) | AY10: KG
B11: PLAQUE | C11: =IF(Eva!C11="","",Eva!C11) | D11: =IF(Eva!D11="","",Eva!D11) | E11: =IF(Eva!E11="","",Eva!E11) | F11: =IF(Eva!F11="","",Eva!F11) | G11: =IF(Eva!G11="","",Eva!G11) | H11: =IF(Eva!H11="","",Eva!H11) | I11: =IF(Eva!I11="","",Eva!I11) | J11: =IF(Eva!J11="","",Eva!J11) | ... AX11: =IF(Eva!AX11="","",Eva!AX11) | AY11: PLAQUE
B12: BOP | C12: =IF(Eva!C12="","",Eva!C12) | D12: =IF(Eva!D12="","",Eva!D12) | E12: =IF(Eva!E12="","",Eva!E12) | F12: =IF(Eva!F12="","",Eva!F12) | G12: =IF(Eva!G12="","",Eva!G12) | H12: =IF(Eva!H12="","",Eva!H12) | I12: =IF(Eva!I12="","",Eva!I12) | J12: =IF(Eva!J12="","",Eva!J12) | ... AX12: =IF(Eva!AX12="","",Eva!AX12) | AY12: BOP
B13: CEJ-GM | C13: =IF(OR(Eva!C13="",'Pre-Tx'!C13=""),"",Eva!C13-'Pre-Tx'!C13) | D13: =IF(OR(Eva!D13="",'Pre-Tx'!D13=""),"",Eva!D13-'Pre-Tx'!D13) | E13: =IF(OR(Eva!E13="",'Pre-Tx'!E13=""),"",Eva!E13-'Pre-Tx'!E13) | F13: =IF(OR(Eva!F13="",'Pre-Tx'!F13=""),"",Eva!F13-'Pre-Tx'!F13) | G13: =IF(OR(Eva!G13="",'Pre-Tx'!G13=""),"",Eva!G13-'Pre-Tx'!G13) | H13: =IF(OR(Eva!H13="",'Pre-Tx'!H13=""),"",Eva!H13-'Pre-Tx'!H13) | I13: =IF(OR(Eva!I13="",'Pre-Tx'!I13=""),"",Eva!I13-'Pre-Tx'!I13) | J13: =IF(OR(Eva!J13="",'Pre-Tx'!J13=""),"",Eva!J13-'Pre-Tx'!J13) | ... AX13: =IF(OR(Eva!AX13="",'Pre-Tx'!AX13=""),"",Eva!AX13-'Pre-Tx'!AX13) | AY13: CEJ-GM
B14: PD | C14: =IF(OR(Eva!C14="",'Pre-Tx'!C14=""),"",Eva!C14-'Pre-Tx'!C14) | D14: =IF(OR(Eva!D14="",'Pre-Tx'!D14=""),"",Eva!D14-'Pre-Tx'!D14) | E14: =IF(OR(Eva!E14="",'Pre-Tx'!E14=""),"",Eva!E14-'Pre-Tx'!E14) | F14: =IF(OR(Eva!F14="",'Pre-Tx'!F14=""),"",Eva!F14-'Pre-Tx'!F14) | G14: =IF(OR(Eva!G14="",'Pre-Tx'!G14=""),"",Eva!G14-'Pre-Tx'!G14) | H14: =IF(OR(Eva!H14="",'Pre-Tx'!H14=""),"",Eva!H14-'Pre-Tx'!H14) | I14: =IF(OR(Eva!I14="",'Pre-Tx'!I14=""),"",Eva!I14-'Pre-Tx'!I14) | J14: =IF(OR(Eva!J14="",'Pre-Tx'!J14=""),"",Eva!J14-'Pre-Tx'!J14) | ... AX14: =IF(OR(Eva!AX14="",'Pre-Tx'!AX14=""),"",Eva!AX14-'Pre-Tx'!AX14) | AY14: PD
B15: CAL | C15: =IF(OR(Eva!C15="",'Pre-Tx'!C15=""),"",Eva!C15-'Pre-Tx'!C15) | D15: =IF(OR(Eva!D15="",'Pre-Tx'!D15=""),"",Eva!D15-'Pre-Tx'!D15) | E15: =IF(OR(Eva!E15="",'Pre-Tx'!E15=""),"",Eva!E15-'Pre-Tx'!E15) | F15: =IF(OR(Eva!F15="",'Pre-Tx'!F15=""),"",Eva!F15-'Pre-Tx'!F15) | G15: =IF(OR(Eva!G15="",'Pre-Tx'!G15=""),"",Eva!G15-'Pre-Tx'!G15) | H15: =IF(OR(Eva!H15="",'Pre-Tx'!H15=""),"",Eva!H15-'Pre-Tx'!H15) | I15: =IF(OR(Eva!I15="",'Pre-Tx'!I15=""),"",Eva!I15-'Pre-Tx'!I15) | J15: =IF(OR(Eva!J15="",'Pre-Tx'!J15=""),"",Eva!J15-'Pre-Tx'!J15) | ... AX15: =IF(OR(Eva!AX15="",'Pre-Tx'!AX15=""),"",Eva!AX15-'Pre-Tx'!AX15) | AY15: CAL
A23: PALATAL | B23: CAL | C23: =IF(OR(Eva!C23="",'Pre-Tx'!C23=""),"",Eva!C23-'Pre-Tx'!C23) | D23: =IF(OR(Eva!D23="",'Pre-Tx'!D23=""),"",Eva!D23-'Pre-Tx'!D23) | E23: =IF(OR(Eva!E23="",'Pre-Tx'!E23=""),"",Eva!E23-'Pre-Tx'!E23) | F23: =IF(OR(Eva!F23="",'Pre-Tx'!F23=""),"",Eva!F23-'Pre-Tx'!F23) | G23: =IF(OR(Eva!G23="",'Pre-Tx'!G23=""),"",Eva!G23-'Pre-Tx'!G23) | H23: =IF(OR(Eva!H23="",'Pre-Tx'!H23=""),"",Eva!H23-'Pre-Tx'!H23) | I23: =IF(OR(Eva!I23="",'Pre-Tx'!I23=""),"",Eva!I23-'Pre-Tx'!I23) | J23: =IF(OR(Eva!J23="",'Pre-Tx'!J23=""),"",Eva!J23-'Pre-Tx'!J23) | ... AX23: =IF(OR(Eva!AX23="",'Pre-Tx'!AX23=""),"",Eva!AX23-'Pre-Tx'!AX23) | AY23: CAL
B24: PD | C24: =IF(OR(Eva!C24="",'Pre-Tx'!C24=""),"",Eva!C24-'Pre-Tx'!C24) | D24: =IF(OR(Eva!D24="",'Pre-Tx'!D24=""),"",Eva!D24-'Pre-Tx'!D24) | E24: =IF(OR(Eva!E24="",'Pre-Tx'!E24=""),"",Eva!E24-'Pre-Tx'!E24) | F24: =IF(OR(Eva!F24="",'Pre-Tx'!F24=""),"",Eva!F24-'Pre-Tx'!F24) | G24: =IF(OR(Eva!G24="",'Pre-Tx'!G24=""),"",Eva!G24-'Pre-Tx'!G24) | H24: =IF(OR(Eva!H24="",'Pre-Tx'!H24=""),"",Eva!H24-'Pre-Tx'!H24) | I24: =IF(OR(Eva!I24="",'Pre-Tx'!I24=""),"",Eva!I24-'Pre-Tx'!I24) | J24: =IF(OR(Eva!J24="",'Pre-Tx'!J24=""),"",Eva!J24-'Pre-Tx'!J24) | ... AX24: =IF(OR(Eva!AX24="",'Pre-Tx'!AX24=""),"",Eva!AX24-'Pre-Tx'!AX24) | AY24: PD
B25: CEJ-GM | C25: =IF(OR(Eva!C25="",'Pre-Tx'!C25=""),"",Eva!C25-'Pre-Tx'!C25) | D25: =IF(OR(Eva!D25="",'Pre-Tx'!D25=""),"",Eva!D25-'Pre-Tx'!D25) | E25: =IF(OR(Eva!E25="",'Pre-Tx'!E25=""),"",Eva!E25-'Pre-Tx'!E25) | F25: =IF(OR(Eva!F25="",'Pre-Tx'!F25=""),"",Eva!F25-'Pre-Tx'!F25) | G25: =IF(OR(Eva!G25="",'Pre-Tx'!G25=""),"",Eva!G25-'Pre-Tx'!G25) | H25: =IF(OR(Eva!H25="",'Pre-Tx'!H25=""),"",Eva!H25-'Pre-Tx'!H25) | I25: =IF(OR(Eva!I25="",'Pre-Tx'!I25=""),"",Eva!I25-'Pre-Tx'!I25) | J25: =IF(OR(Eva!J25="",'Pre-Tx'!J25=""),"",Eva!J25-'Pre-Tx'!J25) | ... AX25: =IF(OR(Eva!AX25="",'Pre-Tx'!AX25=""),"",Eva!AX25-'Pre-Tx'!AX25) | AY25: CEJ-GM
B26: BOP | C26: =IF(Eva!C26="","",Eva!C26) | D26: =IF(Eva!D26="","",Eva!D26) | E26: =IF(Eva!E26="","",Eva!E26) | F26: =IF(Eva!F26="","",Eva!F26) | G26: =IF(Eva!G26="","",Eva!G26) | H26: =IF(Eva!H26="","",Eva!H26) | I26: =IF(Eva!I26="","",Eva!I26) | J26: =IF(Eva!J26="","",Eva!J26) | ... AX26: =IF(Eva!AX26="","",Eva!AX26) | AY26: BOP
B27: PLAQUE | C27: =IF(Eva!C27="","",Eva!C27) | D27: =IF(Eva!D27="","",Eva!D27) | E27: =IF(Eva!E27="","",Eva!E27) | F27: =IF(Eva!F27="","",Eva!F27) | G27: =IF(Eva!G27="","",Eva!G27) | H27: =IF(Eva!H27="","",Eva!H27) | I27: =IF(Eva!I27="","",Eva!I27) | J27: =IF(Eva!J27="","",Eva!J27) | ... AX27: =IF(Eva!AX27="","",Eva!AX27) | AY27: PLAQUE
A28: MAXILLA | C28: 18 | F28: 17 | I28: 16 | L28: 15 | O28: 14 | R28: 13 | U28: 12 | X28: 11 | AA28: 21 | AD28: 22 | AG28: 23 | AJ28: 24 | AM28: 25 | AP28: 26 | AS28: 27 | AV28: 28
A31: MANDIBLE | C31: 48 | F31: 47 | I31: 46 | L31: 45 | O31: 44 | R31: 43 | U31: 42 | X31: 41 | AA31: 31 | AD31: 32 | AG31: 33 | AJ31: 34 | AM31: 35 | AP31: 36 | AS31: 37 | AV31: 38
A32: LINGUAL | B32: PLAQUE | C32: =IF(Eva!C32="","",Eva!C32) | D32: =IF(Eva!D32="","",Eva!D32) | E32: =IF(Eva!E32="","",Eva!E32) | F32: =IF(Eva!F32="","",Eva!F32) | G32: =IF(Eva!G32="","",Eva!G32) | H32: =IF(Eva!H32="","",Eva!H32) | I32: =IF(Eva!I32="","",Eva!I32) | J32: =IF(Eva!J32="","",Eva!J32) | ... AX32: =IF(Eva!AX32="","",Eva!AX32) | AY32: PLAQUE
B33: BOP | C33: =IF(Eva!C33="","",Eva!C33) | D33: =IF(Eva!D33="","",Eva!D33) | E33: =IF(Eva!E33="","",Eva!E33) | F33: =IF(Eva!F33="","",Eva!F33) | G33: =IF(Eva!G33="","",Eva!G33) | H33: =IF(Eva!H33="","",Eva!H33) | I33: =IF(Eva!I33="","",Eva!I33) | J33: =IF(Eva!J33="","",Eva!J33) | ... AX33: =IF(Eva!AX33="","",Eva!AX33) | AY33: BOP
B34: CEJ-GM | C34: =IF(OR(Eva!C34="",'Pre-Tx'!C34=""),"",Eva!C34-'Pre-Tx'!C34) | D34: =IF(OR(Eva!D34="",'Pre-Tx'!D34=""),"",Eva!D34-'Pre-Tx'!D34) | E34: =IF(OR(Eva!E34="",'Pre-Tx'!E34=""),"",Eva!E34-'Pre-Tx'!E34) | F34: =IF(OR(Eva!F34="",'Pre-Tx'!F34=""),"",Eva!F34-'Pre-Tx'!F34) | G34: =IF(OR(Eva!G34="",'Pre-Tx'!G34=""),"",Eva!G34-'Pre-Tx'!G34) | H34: =IF(OR(Eva!H34="",'Pre-Tx'!H34=""),"",Eva!H34-'Pre-Tx'!H34) | I34: =IF(OR(Eva!I34="",'Pre-Tx'!I34=""),"",Eva!I34-'Pre-Tx'!I34) | J34: =IF(OR(Eva!J34="",'Pre-Tx'!J34=""),"",Eva!J34-'Pre-Tx'!J34) | ... AX34: =IF(OR(Eva!AX34="",'Pre-Tx'!AX34=""),"",Eva!AX34-'Pre-Tx'!AX34) | AY34: CEJ-GM
B35: PD | C35: =IF(OR(Eva!C35="",'Pre-Tx'!C35=""),"",Eva!C35-'Pre-Tx'!C35) | D35: =IF(OR(Eva!D35="",'Pre-Tx'!D35=""),"",Eva!D35-'Pre-Tx'!D35) | E35: =IF(OR(Eva!E35="",'Pre-Tx'!E35=""),"",Eva!E35-'Pre-Tx'!E35) | F35: =IF(OR(Eva!F35="",'Pre-Tx'!F35=""),"",Eva!F35-'Pre-Tx'!F35) | G35: =IF(OR(Eva!G35="",'Pre-Tx'!G35=""),"",Eva!G35-'Pre-Tx'!G35) | H35: =IF(OR(Eva!H35="",'Pre-Tx'!H35=""),"",Eva!H35-'Pre-Tx'!H35) | I35: =IF(OR(Eva!I35="",'Pre-Tx'!I35=""),"",Eva!I35-'Pre-Tx'!I35) | J35: =IF(OR(Eva!J35="",'Pre-Tx'!J35=""),"",Eva!J35-'Pre-Tx'!J35) | ... AX35: =IF(OR(Eva!AX35="",'Pre-Tx'!AX35=""),"",Eva!AX35-'Pre-Tx'!AX35) | AY35: PD
B36: CAL | C36: =IF(OR(Eva!C36="",'Pre-Tx'!C36=""),"",Eva!C36-'Pre-Tx'!C36) | D36: =IF(OR(Eva!D36="",'Pre-Tx'!D36=""),"",Eva!D36-'Pre-Tx'!D36) | E36: =IF(OR(Eva!E36="",'Pre-Tx'!E36=""),"",Eva!E36-'Pre-Tx'!E36) | F36: =IF(OR(Eva!F36="",'Pre-Tx'!F36=""),"",Eva!F36-'Pre-Tx'!F36) | G36: =IF(OR(Eva!G36="",'Pre-Tx'!G36=""),"",Eva!G36-'Pre-Tx'!G36) | H36: =IF(OR(Eva!H36="",'Pre-Tx'!H36=""),"",Eva!H36-'Pre-Tx'!H36) | I36: =IF(OR(Eva!I36="",'Pre-Tx'!I36=""),"",Eva!I36-'Pre-Tx'!I36) | J36: =IF(OR(Eva!J36="",'Pre-Tx'!J36=""),"",Eva!J36-'Pre-Tx'!J36) | ... AX36: =IF(OR(Eva!AX36="",'Pre-Tx'!AX36=""),"",Eva!AX36-'Pre-Tx'!AX36) | AY36: CAL
A44: BUCCAL | B44: CAL | C44: =IF(OR(Eva!C44="",'Pre-Tx'!C44=""),"",Eva!C44-'Pre-Tx'!C44) | D44: =IF(OR(Eva!D44="",'Pre-Tx'!D44=""),"",Eva!D44-'Pre-Tx'!D44) | E44: =IF(OR(Eva!E44="",'Pre-Tx'!E44=""),"",Eva!E44-'Pre-Tx'!E44) | F44: =IF(OR(Eva!F44="",'Pre-Tx'!F44=""),"",Eva!F44-'Pre-Tx'!F44) | G44: =IF(OR(Eva!G44="",'Pre-Tx'!G44=""),"",Eva!G44-'Pre-Tx'!G44) | H44: =IF(OR(Eva!H44="",'Pre-Tx'!H44=""),"",Eva!H44-'Pre-Tx'!H44) | I44: =IF(OR(Eva!I44="",'Pre-Tx'!I44=""),"",Eva!I44-'Pre-Tx'!I44) | J44: =IF(OR(Eva!J44="",'Pre-Tx'!J44=""),"",Eva!J44-'Pre-Tx'!J44) | ... AX44: =IF(OR(Eva!AX44="",'Pre-Tx'!AX44=""),"",Eva!AX44-'Pre-Tx'!AX44) | AY44: CAL
B45: PD | C45: =IF(OR(Eva!C45="",'Pre-Tx'!C45=""),"",Eva!C45-'Pre-Tx'!C45) | D45: =IF(OR(Eva!D45="",'Pre-Tx'!D45=""),"",Eva!D45-'Pre-Tx'!D45) | E45: =IF(OR(Eva!E45="",'Pre-Tx'!E45=""),"",Eva!E45-'Pre-Tx'!E45) | F45: =IF(OR(Eva!F45="",'Pre-Tx'!F45=""),"",Eva!F45-'Pre-Tx'!F45) | G45: =IF(OR(Eva!G45="",'Pre-Tx'!G45=""),"",Eva!G45-'Pre-Tx'!G45) | H45: =IF(OR(Eva!H45="",'Pre-Tx'!H45=""),"",Eva!H45-'Pre-Tx'!H45) | I45: =IF(OR(Eva!I45="",'Pre-Tx'!I45=""),"",Eva!I45-'Pre-Tx'!I45) | J45: =IF(OR(Eva!J45="",'Pre-Tx'!J45=""),"",Eva!J45-'Pre-Tx'!J45) | ... AX45: =IF(OR(Eva!AX45="",'Pre-Tx'!AX45=""),"",Eva!AX45-'Pre-Tx'!AX45) | AY45: PD
B46: CEJ-GM | C46: =IF(OR(Eva!C46="",'Pre-Tx'!C46=""),"",Eva!C46-'Pre-Tx'!C46) | D46: =IF(OR(Eva!D46="",'Pre-Tx'!D46=""),"",Eva!D46-'Pre-Tx'!D46) | E46: =IF(OR(Eva!E46="",'Pre-Tx'!E46=""),"",Eva!E46-'Pre-Tx'!E46) | F46: =IF(OR(Eva!F46="",'Pre-Tx'!F46=""),"",Eva!F46-'Pre-Tx'!F46) | G46: =IF(OR(Eva!G46="",'Pre-Tx'!G46=""),"",Eva!G46-'Pre-Tx'!G46) | H46: =IF(OR(Eva!H46="",'Pre-Tx'!H46=""),"",Eva!H46-'Pre-Tx'!H46) | I46: =IF(OR(Eva!I46="",'Pre-Tx'!I46=""),"",Eva!I46-'Pre-Tx'!I46) | J46: =IF(OR(Eva!J46="",'Pre-Tx'!J46=""),"",Eva!J46-'Pre-Tx'!J46) | ... AX46: =IF(OR(Eva!AX46="",'Pre-Tx'!AX46=""),"",Eva!AX46-'Pre-Tx'!AX46) | AY46: CEJ-GM
B47: BOP | C47: =IF(Eva!C47="","",Eva!C47) | D47: =IF(Eva!D47="","",Eva!D47) | E47: =IF(Eva!E47="","",Eva!E47) | F47: =IF(Eva!F47="","",Eva!F47) | G47: =IF(Eva!G47="","",Eva!G47) | H47: =IF(Eva!H47="","",Eva!H47) | I47: =IF(Eva!I47="","",Eva!I47) | J47: =IF(Eva!J47="","",Eva!J47) | ... AX47: =IF(Eva!AX47="","",Eva!AX47) | AY47: BOP
B48: PLAQUE | C48: =IF(Eva!C48="","",Eva!C48) | D48: =IF(Eva!D48="","",Eva!D48) | E48: =IF(Eva!E48="","",Eva!E48) | F48: =IF(Eva!F48="","",Eva!F48) | G48: =IF(Eva!G48="","",Eva!G48) | H48: =IF(Eva!H48="","",Eva!H48) | I48: =IF(Eva!I48="","",Eva!I48) | J48: =IF(Eva!J48="","",Eva!J48) | ... AX48: =IF(Eva!AX48="","",Eva!AX48) | AY48: PLAQUE
B49: KG | C49: =IF(OR(Eva!C49="",'Pre-Tx'!C49=""),"",Eva!C49-'Pre-Tx'!C49) | D49: =IF(OR(Eva!D49="",'Pre-Tx'!D49=""),"",Eva!D49-'Pre-Tx'!D49) | E49: =IF(OR(Eva!E49="",'Pre-Tx'!E49=""),"",Eva!E49-'Pre-Tx'!E49) | F49: =IF(OR(Eva!F49="",'Pre-Tx'!F49=""),"",Eva!F49-'Pre-Tx'!F49) | G49: =IF(OR(Eva!G49="",'Pre-Tx'!G49=""),"",Eva!G49-'Pre-Tx'!G49) | H49: =IF(OR(Eva!H49="",'Pre-Tx'!H49=""),"",Eva!H49-'Pre-Tx'!H49) | I49: =IF(OR(Eva!I49="",'Pre-Tx'!I49=""),"",Eva!I49-'Pre-Tx'!I49) | J49: =IF(OR(Eva!J49="",'Pre-Tx'!J49=""),"",Eva!J49-'Pre-Tx'!J49) | ... AX49: =IF(OR(Eva!AX49="",'Pre-Tx'!AX49=""),"",Eva!AX49-'Pre-Tx'!AX49) | AY49: KG
A50: MANDIBLE | C50: 48 | F50: 47 | I50: 46 | L50: 45 | O50: 44 | R50: 43 | U50: 42 | X50: 41 | AA50: 31 | AD50: 32 | AG50: 33 | AJ50: 34 | AM50: 35 | AP50: 36 | AS50: 37 | AV50: 38
C52: MISSING TEETH · from the Eva sheet
A53: MAXILLA | C53: 18 | F53: 17 | I53: 16 | L53: 15 | O53: 14 | R53: 13 | U53: 12 | X53: 11 | AA53: 21 | AD53: 22 | AG53: 23 | AJ53: 24 | AM53: 25 | AP53: 26 | AS53: 27 | AV53: 28
A54: X / I | C54: =IF(Eva!C54="","",Eva!C54) | F54: =IF(Eva!F54="","",Eva!F54) | I54: =IF(Eva!I54="","",Eva!I54) | L54: =IF(Eva!L54="","",Eva!L54) | O54: =IF(Eva!O54="","",Eva!O54) | R54: =IF(Eva!R54="","",Eva!R54) | U54: =IF(Eva!U54="","",Eva!U54) | X54: =IF(Eva!X54="","",Eva!X54) | AA54: =IF(Eva!AA54="","",Eva!AA54) | AD54: =IF(Eva!AD54="","",Eva!AD54) | AG54: =IF(Eva!AG54="","",Eva!AG54) | AJ54: =IF(Eva!AJ54="","",Eva!AJ54) | AM54: =IF(Eva!AM54="","",Eva!AM54) | AP54: =IF(Eva!AP54="","",Eva!AP54) | AS54: =IF(Eva!AS54="","",Eva!AS54) | AV54: =IF(Eva!AV54="","",Eva!AV54)
A55: MANDIBLE | C55: 48 | F55: 47 | I55: 46 | L55: 45 | O55: 44 | R55: 43 | U55: 42 | X55: 41 | AA55: 31 | AD55: 32 | AG55: 33 | AJ55: 34 | AM55: 35 | AP55: 36 | AS55: 37 | AV55: 38
A56: X / I | C56: =IF(Eva!C56="","",Eva!C56) | F56: =IF(Eva!F56="","",Eva!F56) | I56: =IF(Eva!I56="","",Eva!I56) | L56: =IF(Eva!L56="","",Eva!L56) | O56: =IF(Eva!O56="","",Eva!O56) | R56: =IF(Eva!R56="","",Eva!R56) | U56: =IF(Eva!U56="","",Eva!U56) | X56: =IF(Eva!X56="","",Eva!X56) | AA56: =IF(Eva!AA56="","",Eva!AA56) | AD56: =IF(Eva!AD56="","",Eva!AD56) | AG56: =IF(Eva!AG56="","",Eva!AG56) | AJ56: =IF(Eva!AJ56="","",Eva!AJ56) | AM56: =IF(Eva!AM56="","",Eva!AM56) | AP56: =IF(Eva!AP56="","",Eva!AP56) | AS56: =IF(Eva!AS56="","",Eva!AS56) | AV56: =IF(Eva!AV56="","",Eva!AV56)
